Workbook

Sheet Samenvatting
A1: Lostock Fabric — Meetstaten Samenvatting
A2: Productie- en inmeetgegevens isolatiematrassen (SIB Isolatie / Hotrema)
A4: Opdrachtgever: | B4: Hotrema | D4: PROJECT TOTAAL (ST.) | G4: AANTAL MATRASSEN (ST.) | J4: AANTAL PETTEN | M4: DATABASE DETAILS (ST.)
A5: Project: | B5: Lostock Fabric | D5: ='Meetstaten Pagina's'!G47 | G5: ='Meetstaten Pagina's'!E47 | J5: ='Meetstaten Pagina's'!F47 | M5: ='Meetstaten Details'!B172
A6: Uitvoering: | B6: Sil-HT700-wol
A7: Inmeters: | B7: JV & RdW (Ron de Wit)
A8: Inmeetperiode: | B8: 9 juni 2026 t/m 12 juni 2026
A9: Rapportagedatum: | B9: 23 juni 2026
A12: Dag | B12: Datum | C12: Project Totaal (st.) | D12: Database Details (st.) | E12: m2 Details (m2) | F12: Gewicht Details (kg) | G12: Waarde Details (€)
A13: 1e dag | B13: 09-06-2026 | C13: 519 | D13: =SUMIFS('Meetstaten Details'!B$4:B$171, 'Meetstaten Details'!R$4:R$171, "09-06-2026") | E13: =SUMIFS('Meetstaten Details'!K$4:K$171, 'Meetstaten Details'!R$4:R$171, "09-06-2026") | F13: =SUMIFS('Meetstaten Details'!P$4:P$171, 'Meetstaten Details'!R$4:R$171, "09-06-2026") | G13: =SUMIFS('Meetstaten Details'!O$4:O$171, 'Meetstaten Details'!R$4:R$171, "09-06-2026")
A14: 2e dag | B14: 10-06-2026 | C14: 339 | D14: =SUMIFS('Meetstaten Details'!B$4:B$171, 'Meetstaten Details'!R$4:R$171, "10-06-2026") | E14: =SUMIFS('Meetstaten Details'!K$4:K$171, 'Meetstaten Details'!R$4:R$171, "10-06-2026") | F14: =SUMIFS('Meetstaten Details'!P$4:P$171, 'Meetstaten Details'!R$4:R$171, "10-06-2026") | G14: =SUMIFS('Meetstaten Details'!O$4:O$171, 'Meetstaten Details'!R$4:R$171, "10-06-2026")
A15: 3e dag | B15: 11-06-2026 | C15: 520 | D15: =SUMIFS('Meetstaten Details'!B$4:B$171, 'Meetstaten Details'!R$4:R$171, "11-06-2026") | E15: =SUMIFS('Meetstaten Details'!K$4:K$171, 'Meetstaten Details'!R$4:R$171, "11-06-2026") | F15: =SUMIFS('Meetstaten Details'!P$4:P$171, 'Meetstaten Details'!R$4:R$171, "11-06-2026") | G15: =SUMIFS('Meetstaten Details'!O$4:O$171, 'Meetstaten Details'!R$4:R$171, "11-06-2026")
A16: 4e dag | B16: 12-06-2026 | C16: 185 | D16: =SUMIFS('Meetstaten Details'!B$4:B$171, 'Meetstaten Details'!R$4:R$171, "12-06-2026") | E16: =SUMIFS('Meetstaten Details'!K$4:K$171, 'Meetstaten Details'!R$4:R$171, "12-06-2026") | F16: =SUMIFS('Meetstaten Details'!P$4:P$171, 'Meetstaten Details'!R$4:R$171, "12-06-2026") | G16: =SUMIFS('Meetstaten Details'!O$4:O$171, 'Meetstaten Details'!R$4:R$171, "12-06-2026")
A17: Totaal | C17: =SUM(C13:C16) | D17: =SUM(D13:D16) | E17: =SUM(E13:E16) | F17: =SUM(F13:F16) | G17: =SUM(G13:G16)

Sheet Meetstaten Details
A1: 46185 | G1: Location | J1: 170
L2: prijs | O2: PRIJS
A3: nummer | B3: Aantal | C3: nummer | D3: omvang | E3: hoogte | F3: Gesp/haken | K3: m2 | N3: labels | P3: kg | Q3: Verdieping | R3: Datum | S3: Inmeter | T3: Bovendoek | U3: Onderdoek
A4: Lostock Fabric | B4: 2 | C4: 278 | D4: 1.1 | E4: 0.55 | F4: G | G4: Turbine Hall | I4: =D4+0.03 | J4: =E4+0.03 | K4: =B4*I4*J4 | L4: 190 | M4: =K4*L4 | N4: =B4*2 | O4: =M4+N4 | P4: =K4*7.12 | Q4: Turbine Hall | R4: 12-06-2026 | S4: Ron | T4: N/A | U4: N/A
A5: Lostock Fabric | B5: 2 | C5: 279 | D5: 1.1 | E5: 0.45 | F5: G | G5: Turbine Hall | I5: =D5+0.03 | J5: =E5+0.03 | K5: =B5*I5*J5 | L5: 190 | M5: =K5*L5 | N5: =B5*2 | O5: =M5+N5 | P5: =K5*7.12 | Q5: Turbine Hall | R5: 12-06-2026 | S5: Ron | T5: N/A | U5: N/A
A6: Lostock Fabric | B6: 2 | C6: 280 | D6: 1.1 | E6: 0.68 | F6: G | G6: Turbine Hall | I6: =D6+0.03 | J6: =E6+0.03 | K6: =B6*I6*J6 | L6: 190 | M6: =K6*L6 | N6: =B6*2 | O6: =M6+N6 | P6: =K6*7.12 | Q6: Turbine Hall | R6: 12-06-2026 | S6: Ron | T6: N/A | U6: N/A
A7: Lostock Fabric | B7: 1 | C7: 281 | D7: 1.8 | E7: 0.36 | F7: G/H | G7: Turbine Hall | I7: =D7+0.03 | J7: =E7+0.03 | K7: =B7*I7*J7 | L7: 190 | M7: =K7*L7 | N7: =B7*2 | O7: =M7+N7 | P7: =K7*7.12 | Q7: Turbine Hall | R7: 12-06-2026 | S7: Peter | T7: log | U7: N/A
A8: Lostock Fabric | B8: 1 | C8: 281 | D8: 0.57 | E8: 0.57 | F8: G/H | G8: Turbine Hall | I8: =D8+0.03 | J8: =E8+0.03 | K8: =B8*I8*J8 | L8: 190 | M8: =K8*L8 | N8: =B8*2 | O8: =M8+N8 | P8: =K8*7.12 | Q8: Turbine Hall | R8: 12-06-2026 | S8: Peter | T8: log | U8: N/A
A9: Lostock Fabric | B9: 1 | C9: 282 | D9: 0.36 | E9: 0.3 | F9: H | G9: Turbine Hall | I9: =D9+0.03 | J9: =E9+0.03 | K9: =B9*I9*J9 | L9: 190 | M9: =K9*L9 | N9: =B9*2 | O9: =M9+N9 | P9: =K9*7.12 | Q9: Turbine Hall | R9: 12-06-2026 | S9: Ron | T9: N/A | U9: N/A
A10: Lostock Fabric | B10: 1 | C10: 283 | D10: 0.36 | E10: 0.26 | F10: H | G10: Turbine Hall | I10: =D10+0.03 | J10: =E10+0.03 | K10: =B10*I10*J10 | L10: 190 | M10: =K10*L10 | N10: =B10*2 | O10: =M10+N10 | P10: =K10*7.12 | Q10: Turbine Hall | R10: 12-06-2026 | S10: Ron | T10: N/A | U10: N/A
A11: Lostock Fabric | B11: 1 | C11: 284 | D11: 0.36 | E11: 0.46 | F11: H | G11: Turbine Hall | I11: =D11+0.03 | J11: =E11+0.03 | K11: =B11*I11*J11 | L11: 190 | M11: =K11*L11 | N11: =B11*2 | O11: =M11+N11 | P11: =K11*7.12 | Q11: Turbine Hall | R11: 12-06-2026 | S11: Ron | T11: N/A | U11: N/A
A12: Lostock Fabric | B12: 2 | C12: 285 | D12: 0.66 | E12: 0.28 | F12: H | G12: Turbine Hall | I12: =D12+0.03 | J12: =E12+0.03 | K12: =B12*I12*J12 | L12: 190 | M12: =K12*L12 | N12: =B12*2 | O12: =M12+N12 | P12: =K12*7.12 | Q12: Turbine Hall | R12: 12-06-2026 | S12: Ron | T12: N/A | U12: N/A
A13: Lostock Fabric | B13: 1 | C13: 286 | D13: 1.36 | E13: 0.65 | F13: G | G13: Turbine Hall | I13: =D13+0.03 | J13: =E13+0.03 | K13: =B13*I13*J13 | L13: 190 | M13: =K13*L13 | N13: =B13*2 | O13: =M13+N13 | P13: =K13*7.12 | Q13: Turbine Hall | R13: 12-06-2026 | S13: Ron | T13: N/A | U13: N/A
A14: Lostock Fabric | B14: 1 | C14: 287 | D14: 1.36 | E14: 0.66 | F14: G | G14: Turbine Hall | I14: =D14+0.03 | J14: =E14+0.03 | K14: =B14*I14*J14 | L14: 190 | M14: =K14*L14 | N14: =B14*2 | O14: =M14+N14 | P14: =K14*7.12 | Q14: Turbine Hall | R14: 12-06-2026 | S14: Ron | T14: N/A | U14: N/A
A15: Lostock Fabric | B15: 1 | C15: 288 | D15: 0.4 | E15: 0.48 | F15: H | G15: Turbine Hall | I15: =D15+0.03 | J15: =E15+0.03 | K15: =B15*I15*J15 | L15: 190 | M15: =K15*L15 | N15: =B15*2 | O15: =M15+N15 | P15: =K15*7.12 | Q15: Turbine Hall | R15: 12-06-2026 | S15: Ron | T15: N/A | U15: N/A
... A71: Lostock Fabric | B71: 1 | C71: 333 | D71: 0.75 | E71: 0.32 | F71: G | G71: Turbine Hall | I71: =D71+0.03 | J71: =E71+0.03 | K71: =B71*I71*J71 | L71: 190 | M71: =K71*L71 | N71: =B71*2 | O71: =M71+N71 | P71: =K71*7.12 | Q71: Turbine Hall | R71: 12-06-2026 | S71: Ron | T71: N/A | U71: N/A
A72: Lostock Fabric | B72: 12 | C72: 1 | D72: 0.66 | E72: 0.29 | F72: G | I72: =D72+0.03 | J72: =E72+0.03 | K72: =B72*I72*J72 | L72: 190 | M72: =K72*L72 | N72: =B72*2 | O72: =M72+N72 | P72: =K72*7.12 | Q72: Dak | R72: 09-06-2026 | S72: Peter | T72: N/A | U72: N/A
A73: Lostock Fabric | B73: 24 | C73: 2 | D73: 1.03 | E73: 0.28 | F73: G/H | I73: =D73+0.03 | J73: =E73+0.03 | K73: =B73*I73*J73 | L73: 190 | M73: =K73*L73 | N73: =B73*2 | O73: =M73+N73 | P73: =K73*7.12 | Q73: Dak | R73: 09-06-2026 | S73: Peter | T73: /56 | U73: /56
A74: Lostock Fabric | B74: 24 | C74: 2 | D74: 0.33 | E74: 0.33 | F74: G/H | I74: =D74+0.03 | J74: =E74+0.03 | K74: =B74*I74*J74 | L74: 190 | M74: =K74*L74 | N74: =B74*2 | O74: =M74+N74 | P74: =K74*7.12 | Q74: Dak | R74: 09-06-2026 | S74: Peter | T74: /56 | U74: /56
A75: Lostock Fabric | B75: 36 | C75: 3 | D75: 0.72 | E75: 0.14 | F75: G/H | I75: =D75+0.03 | J75: =E75+0.03 | K75: =B75*I75*J75 | L75: 190 | M75: =K75*L75 | N75: =B75*2 | O75: =M75+N75 | P75: =K75*7.12 | Q75: Dak | R75: 09-06-2026 | S75: Peter | T75: be | U75: N/A
A76: Lostock Fabric | B76: 36 | C76: 3 | D76: 0.23 | E76: 0.23 | F76: G/H | I76: =D76+0.03 | J76: =E76+0.03 | K76: =B76*I76*J76 | L76: 190 | M76: =K76*L76 | N76: =B76*2 | O76: =M76+N76 | P76: =K76*7.12 | Q76: Dak | R76: 09-06-2026 | S76: Peter | T76: be | U76: N/A
A77: Lostock Fabric | B77: 12 | C77: 4 | D77: 0.75 | E77: 0.32 | F77: G | I77: =D77+0.03 | J77: =E77+0.03 | K77: =B77*I77*J77 | L77: 190 | M77: =K77*L77 | N77: =B77*2 | O77: =M77+N77 | P77: =K77*7.12 | Q77: Dak | R77: 09-06-2026 | S77: Peter | T77: N/A | U77: N/A
A78: Lostock Fabric | B78: 36 | C78: 5 | D78: 0.7 | E78: 0.56 | F78: G | I78: =D78+0.03 | J78: =E78+0.03 | K78: =B78*I78*J78 | L78: 190 | M78: =K78*L78 | N78: =B78*2 | O78: =M78+N78 | P78: =K78*7.12 | Q78: Dak | R78: 09-06-2026 | S78: Peter | T78: /56 | U78: /56
A79: Lostock Fabric | B79: 12 | C79: 6 | D79: 1.03 | E79: 0.32 | F79: G | I79: =D79+0.03 | J79: =E79+0.03 | K79: =B79*I79*J79 | L79: 190 | M79: =K79*L79 | N79: =B79*2 | O79: =M79+N79 | P79: =K79*7.12 | Q79: Dak | R79: 09-06-2026 | S79: Peter | T79: /56 | U79: /56
A80: Lostock Fabric | B80: 12 | C80: 7 | D80: 2.57 | E80: 0.36 | F80: G/H | I80: =D80+0.03 | J80: =E80+0.03 | K80: =B80*I80*J80 | L80: 190 | M80: =K80*L80 | N80: =B80*2 | O80: =M80+N80 | P80: =K80*7.12 | Q80: Dak | R80: 09-06-2026 | S80: Peter | T80: N/A | U80: N/A
A81: Lostock Fabric | B81: 12 | C81: 7 | D81: 0.82 | E81: 0.82 | F81: G/H | I81: =D81+0.03 | J81: =E81+0.03 | K81: =B81*I81*J81 | L81: 190 | M81: =K81*L81 | N81: =B81*2 | O81: =M81+N81 | P81: =K81*7.12 | Q81: Dak | R81: 09-06-2026 | S81: Peter | T81: N/A | U81: N/A
A82: Lostock Fabric | B82: 12 | C82: 8 | D82: 2.91 | E82: 0.58 | F82: G | I82: =D82+0.03 | J82: =E82+0.03 | K82: =B82*I82*J82 | L82: 190 | M82: =K82*L82 | N82: =B82*2 | O82: =M82+N82 | P82: =K82*7.12 | Q82: Dak | R82: 09-06-2026 | S82: Peter | T82: N/A | U82: N/A
A83: Lostock Fabric | B83: 16 | C83: 9 | D83: 0.75 | E83: 0.28 | F83: G | I83: =D83+0.03 | J83: =E83+0.03 | K83: =B83*I83*J83 | L83: 190 | M83: =K83*L83 | N83: =B83*2 | O83: =M83+N83 | P83: =K83*7.12 | Q83: Dak | R83: 09-06-2026 | S83: Peter | T83: N/A | U83: N/A
... A120: Lostock Fabric | B120: 1 | C120: 38 | D120: 0.38 | E120: 0.4 | F120: NO G&H | I120: =D120+0.03 | J120: =E120+0.03 | K120: =B120*I120*J120 | L120: 190 | M120: =K120*L120 | N120: =B120*2 | O120: =M120+N120 | P120: =K120*7.12 | Q120: Ground Floor | R120: 09-06-2026 | S120: Peter | T120: 4g | U120: N/A
A121: Lostock Fabric | B121: 16 | C121: 39 | D121: 0.83 | E121: 0.21 | I121: =D121+0.03 | J121: =E121+0.03 | K121: =B121*I121*J121 | L121: 190 | M121: =K121*L121 | N121: =B121*2 | O121: =M121+N121 | P121: =K121*7.12 | Q121: Ground Floor | R121: 09-06-2026 | S121: Peter | T121: 5 Zs | U121: N/A
A122: Lostock Fabric | B122: 16 | C122: 39 | D122: 0.26 | E122: 0.26 | I122: =D122+0.03 | J122: =E122+0.03 | K122: =B122*I122*J122 | L122: 190 | M122: =K122*L122 | N122: =B122*2 | O122: =M122+N122 | P122: =K122*7.12 | Q122: Ground Floor | R122: 09-06-2026 | S122: Peter | T122: 5 Zs | U122: N/A
A123: Lostock Fabric | B123: 4 | C123: 40 | D123: 0.9 | E123: 0.9 | I123: =D123+0.03 | J123: =E123+0.03 | K123: =B123*I123*J123 | L123: 190 | M123: =K123*L123 | N123: =B123*2 | O123: =M123+N123 | P123: =K123*7.12 | Q123: Dak | R123: 09-06-2026 | S123: Peter | T123: N/A | U123: N/A
A124: Lostock Fabric | B124: 4 | C124: 41 | D124: 1.67 | E124: 0.89 | I124: =D124+0.03 | J124: =E124+0.03 | K124: =B124*I124*J124 | L124: 190 | M124: =K124*L124 | N124: =B124*2 | O124: =M124+N124 | P124: =K124*7.12 | Q124: Dak | R124: 09-06-2026 | S124: Peter | T124: N/A | U124: N/A
A125: Lostock Fabric | B125: 4 | C125: 41 | D125: 0.53 | E125: 0.53 | I125: =D125+0.03 | J125: =E125+0.03 | K125: =B125*I125*J125 | L125: 190 | M125: =K125*L125 | N125: =B125*2 | O125: =M125+N125 | P125: =K125*7.12 | Q125: Dak | R125: 09-06-2026 | S125: Peter | T125: N/A | U125: N/A
A126: Lostock Fabric | B126: 8 | C126: 42 | D126: 1.04 | E126: 0.37 | I126: =D126+0.03 | J126: =E126+0.03 | K126: =B126*I126*J126 | L126: 190 | M126: =K126*L126 | N126: =B126*2 | O126: =M126+N126 | P126: =K126*7.12 | Q126: Dak | R126: 09-06-2026 | S126: Peter | T126: N/A | U126: N/A
A127: Lostock Fabric | B127: 4 | C127: 43 | D127: 1.67 | E127: 0.97 | I127: =D127+0.03 | J127: =E127+0.03 | K127: =B127*I127*J127 | L127: 190 | M127: =K127*L127 | N127: =B127*2 | O127: =M127+N127 | P127: =K127*7.12 | Q127: Dak | R127: 09-06-2026 | S127: Peter | T127: N/A | U127: N/A
A128: Lostock Fabric | B128: 4 | C128: 43 | D128: 0.53 | E128: 0.53 | I128: =D128+0.03 | J128: =E128+0.03 | K128: =B128*I128*J128 | L128: 190 | M128: =K128*L128 | N128: =B128*2 | O128: =M128+N128 | P128: =K128*7.12 | Q128: Dak | R128: 09-06-2026 | S128: Peter | T128: N/A | U128: N/A
A129: Lostock Fabric | B129: 4 | C129: 44 | D129: 0.63 | E129: 1.1 | I129: =D129+0.03 | J129: =E129+0.03 | K129: =B129*I129*J129 | L129: 190 | M129: =K129*L129 | N129: =B129*2 | O129: =M129+N129 | P129: =K129*7.12 | Q129: 2nd Floor | R129: 10-06-2026 | S129: Peter | T129: N/A | U129: N/A
A130: Lostock Fabric | B130: 4 | C130: 44 | D130: 0.2 | E130: 0.2 | I130: =D130+0.03 | J130: =E130+0.03 | K130: =B130*I130*J130 | L130: 190 | M130: =K130*L130 | N130: =B130*2 | O130: =M130+N130 | P130: =K130*7.12 | Q130: 2nd Floor | R130: 10-06-2026 | S130: Peter | T130: N/A | U130: N/A
A131: Lostock Fabric | B131: 8 | C131: 45 | D131: 0.36 | E131: 0.16 | I131: =D131+0.03 | J131: =E131+0.03 | K131: =B131*I131*J131 | L131: 190 | M131: =K131*L131 | N131: =B131*2 | O131: =M131+N131 | P131: =K131*7.12 | Q131: Dak | R131: 10-06-2026 | S131: Peter | T131: N/A | U131: N/A
...

Sheet Meetstaten Pagina's
A1: Pagina | B1: Datum | C1: Dag | D1: Sectie | E1: Matrassen (st.) | F1: Petten (st.) | G1: Totaal Items | H1: Foto Pagina's | I1: Opmerkingen
A2: 2 | B2: 09-06-2026 | C2: 1e dag | D2: Sectie 1 | E2: 156 | F2: 72 | G2: =E2+F2 | H2: 5-19 | I2: Geverifieerd
A3: 3 | B3: 09-06-2026 | C3: 1e dag | D3: Sectie 1 | E3: 108 | F3: 56 | G3: =E3+F3 | H3: 5-19 | I3: Geverifieerd
A4: 4 | B4: 09-06-2026 | C4: 1e dag | D4: Sectie 1 | E4: 43 | F4: 6 | G4: =E4+F4 | H4: 5-19 | I4: Geverifieerd; Box 22 marked NV is meegeteld
A5: 20 | B5: 09-06-2026 | C5: 1e dag | D5: Sectie 2 | E5: 5 | F5: 5 | G5: =E5+F5 | H5: 23-35 | I5: Geverifieerd
A6: 21 | B6: 09-06-2026 | C6: 1e dag | D6: Sectie 2 | E6: 8 | F6: 0 | G6: =E6+F6 | H6: 23-35 | I6: Geverifieerd; Geen haken
A7: 22 | B7: 09-06-2026 | C7: 1e dag | D7: Sectie 2 | E7: 36 | F7: 24 | G7: =E7+F7 | H7: 23-35 | I7: Geverifieerd
A8: 36 | B8: 10-06-2026 | C8: 2e dag | D8: Sectie 3 | E8: 44 | F8: 16 | G8: =E8+F8 | H8: 38-40 | I8: Geverifieerd; Box 50 marked NV is meegeteld
A9: 37 | B9: 10-06-2026 | C9: 2e dag | D9: Sectie 3 | E9: 18 | F9: 4 | G9: =E9+F9 | H9: 38-40 | I9: Geverifieerd
A10: 41 | B10: 10-06-2026 | C10: 2e dag | D10: Sectie 4 | E10: 28 | F10: 18 | G10: =E10+F10 | H10: 42 | I10: Geverifieerd
A11: 43 | B11: 10-06-2026 | C11: 2e dag | D11: Sectie 5 | E11: 26 | F11: 4 | G11: =E11+F11 | H11: 44-46 | I11: Geverifieerd; Incl. doorgestreepte matrassen
A12: 47 | B12: 10-06-2026 | C12: 2e dag | D12: Sectie 6 | E12: 20 | F12: 4 | G12: =E12+F12 | H12: 48 | I12: Geverifieerd
A13: 49 | B13: 10-06-2026 | C13: 2e dag | D13: Sectie 7 | E13: 12 | F13: 1 | G13: =E13+F13 | H13: 50-51 | I13: Geverifieerd
... A45: 147 | B45: 12-06-2026 | C45: 4e dag | D45: Sectie 15 | E45: 3 | F45: 0 | G45: =E45+F45 | H45: 148-155 | I45: Geverifieerd
A46: Extra / Lijstbestellingen (Repetities) | E46: 127 | F46: 0 | G46: =E46+F46 | I46: Standard repetities zonder tekening (108 dag 3, 19 dag 4)
A47: Totaal | E47: =SUM(E2:E46) | F47: =SUM(F2:F46) | G47: =SUM(G2:G46)
